Workbook
Name Slicer_Platform: #N/A

Sheet Engagement Analysis Task-2
A1: Platform | B1: Average of Engagement Rate
A2: Facebook | B2: 0.1219729
A3: Instagram | B3: 0.19329258
A4: Twitter | B4: 0.14368407
A5: YouTube | B5: 0.13118494
A6: Grand Total | B6: 0.14828272
A22: TOP 10 Tesla Post By Engagement Rate
A23: Post ID | B23: Platform | C23: Date | D23: Content Type | E23: Post Text | F23: Likes | G23: Shares | H23: Comments | I23: Impressions | J23: Reach | K23: Clicks | L23: Hashtags 1 | M23: Hashtags 2 | N23: Hashtags 3 | O23: Campaign_Name | P23: Engagement Rate
A24: {=_xlfn._xlws.FILTER(Posts!A2:P301,Posts!P2:P301>=LARGE(Posts!P2:P301,10))} -> P220 | B24: Instagram | C24: 2024-06-02 | D24: Story | E24: Check out our latest story on instagram! | F24: 84 | G24: 897 | H24: 85 | I24: 588 | J24: 8 | K24: 12 | L24: #EVRevolution | M24: 0 | N24: 0 | O24: 0 | P24: 1.8129252
A25: P058 | B25: Instagram | C25: 2025-04-15 | D25: Reel | E25: Check out our latest reel on instagram! | F25: 103 | G25: 770 | H25: 19 | I25: 1030 | J25: 410 | K25: 262 | L25: #TeslaCoInnovation | M25: 0 | N25: 0 | O25: SustainabilityDrive | P25: 0.86601942
A26: P232 | B26: Twitter | C26: 2025-04-29 | D26: Story | E26: Check out our latest story on twitter! | F26: 249 | G26: 592 | H26: 230 | I26: 1494 | J26: 1044 | K26: 201 | L26: #EVRevolution | M26: 0 | N26: 0 | O26: SustainabilityDrive | P26: 0.71686747
A27: P178 | B27: Instagram | C27: 2024-11-07 | D27: Video | E27: Check out our latest video on instagram! | F27: 129 | G27: 643 | H27: 136 | I27: 1290 | J27: 839 | K27: 238 | L27: #TeslaCoInnovation | M27: 0 | N27: 0 | O27: SustainabilityDrive | P27: 0.70387597
A28: P175 | B28: Instagram | C28: 2025-01-17 | D28: Reel | E28: Check out our latest reel on instagram! | F28: 142 | G28: 784 | H28: 183 | I28: 1704 | J28: 995 | K28: 154 | L28: #FutureOfDriving | M28: 0 | N28: 0 | O28: SustainabilityDrive | P28: 0.6508216
A29: P062 | B29: Twitter | C29: 2024-11-22 | D29: Carousel | E29: Check out our latest carousel on twitter! | F29: 53 | G29: 81 | H29: 379 | I29: 954 | J29: 7 | K29: 148 | L29: #TeslaCoInnovation | M29: 0 | N29: 0 | O29: FSDUpdate | P29: 0.53773585
A30: P264 | B30: Twitter | C30: 2025-01-30 | D30: Image | E30: Check out our latest image on twitter! | F30: 59 | G30: 163 | H30: 93 | I30: 590 | J30: 475 | K30: 293 | L30: #TeslaCoInnovation | M30: 0 | N30: 0 | O30: ModelYCampaign | P30: 0.53389831
A31: P143 | B31: YouTube | C31: 2024-10-02 | D31: Carousel | E31: Check out our latest carousel on youtube! | F31: 80 | G31: 362 | H31: 80 | I31: 1040 | J31: 349 | K31: 117 | L31: #TeslaCoInnovation | M31: 0 | N31: 0 | O31: FSDUpdate | P31: 0.50192308
A32: P210 | B32: YouTube | C32: 2025-02-19 | D32: Image | E32: Check out our latest image on youtube! | F32: 257 | G32: 966 | H32: 398 | I32: 3341 | J32: 2753 | K32: 287 | L32: #FutureOfDriving | M32: 0 | N32: 0 | O32: CybertruckLaunch | P32: 0.48518408
A33: P070 | B33: Facebook | C33: 2025-04-02 | D33: Video | E33: Check out our latest video on facebook! | F33: 199 | G33: 772 | H33: 400 | I33: 3582 | J33: 2988 | K33: 43 | L33: #TeslaCoInnovation | M33: 0 | N33: 0 | O33: 0 | P33: 0.38274707
A43: Content Type | B43: Sum of Likes | C43: Sum of Shares | D43: Sum of Comments
A44: Carousel | B44: 24926 | C44: 6305 | D44: 2422
A45: Image | B45: 23903 | C45: 4310 | D45: 2077
A46: Reel | B46: 32400 | C46: 4577 | D46: 2668
A47: Story | B47: 31968 | C47: 3866 | D47: 2012
A48: Text | B48: 27067 | C48: 3928 | D48: 1052
A49: Video | B49: 31285 | C49: 5586 | D49: 2589
A50: Grand Total | B50: 171549 | C50: 28572 | D50: 12820
A65: Unique Hashtags | B65: Average of Clicks
A66: #AnytimeIsTeslaTime | B66: 154
A67: #BetterWithTesla | B67: 238
A68: #EVRevolution | B68: 262
A69: #FutureOfDriving | B69: 201
A70: #SmoothLikeNitroTesla | B70: 148
A71: #TeslaCoInnovation | B71: 12
A72: (blank) | B72: 150.85374
A73: Grand Total | B73: 151.22
A83: #BetterWithTesla, #EVRevolution, #FutureOfDriving are top 3 performing Hashtags with the highest average clicks per post by Hashtags.

Sheet Platform Analysis task-3
A3: Platform | B3: Average of Engagement Rate
A4: Facebook | B4: 0.1219729
A5: Instagram | B5: 0.19329258
A6: Twitter | B6: 0.14368407
A7: YouTube | B7: 0.13118494
A8: Grand Total | B8: 0.14828272
A17: Instagram show the highest average engagement rate, slightly higher than Facebook, Twitter and YouTube. This indicates that Tesla’s audience interacts slightly more with posts on Instagram compared to the other platforms.
A25: Platform | B25: Average of Net_Growth
A26: Facebook | B26: 711.14
A27: Instagram | B27: 960.08
A28: Twitter | B28: 823.54
A29: YouTube | B29: 707.34
A30: Grand Total | B30: 800.525
A40: Instagram and Twitter show higher average net follower growth compared to other platforms, indicating stronger audience acquisition performance despite inconsistencies in total follower counts.
A53: Platform | B53: Sum of Total Engagement | C53: Average of Ad_Spend | D53: Efficiency %
A54: Facebook | B54: 305242 | C54: 27590.78 | D54: =B54/C54/100 -> 0.11063188
A55: Instagram | B55: 263579 | C55: 23287.46 | D55: =B55/C55/100 -> 0.11318495
A56: Twitter | B56: 256005 | C56: 21207.14 | D56: =B56/C56/100 -> 0.12071642
A57: YouTube | B57: 212941 | C57: 24572.94 | D57: =B57/C57/100 -> 0.086656704
A58: Grand Total | B58: 1037767 | C58: 24164.58
A65: Advise: Should Tesla focus on Twitter + YouTube (product announcements + demos) or maintain a multi-platform strategy?
A69: The analysis shows that while Facebook generates the highest total engagement, it also has the highest ad spend, indicating lower efficiency compared to other platforms. Instagram and Twitter deliver relatively high engagement with lower ad spend, making them more cost-effective platforms. On the other hand, YouTube shows lower engagement despite higher investment, suggesting weaker performance. Therefore, Tesla should maintain a multi-platform strategy while optimizing budget allocation. More focus should be placed on Instagram and Twitter for cost-efficient engagement

Sheet Hashtag & Content Strategy T-4
A3: Unique Hashtags | B3: Sum of Hashtag uses count
A4: #TeslaCoInnovation | B4: 107
A5: #FutureOfDriving | B5: 103
A6: #EVRevolution | B6: 102
A7: #AnytimeIsTeslaTime | B7: 15
A8: #BetterWithTesla | B8: 7
A9: #SmoothLikeNitroTesla | B9: 5
A10: (blank)
A11: Grand Total | B11: 339
A24: Meaning: If any post having hashtag Ex: "#EVRevolution" if it found on Hashtag column 1, 2, or 3 then includes the matrics of that post.
A25: Hashtags Performance Table (using Conditional Aggregation)
A28: Hashtag | B28: Avg Likes | C28: Avg Shares | D28: Avg Comments | E28: Avg Clicks | F28: Avg Engagement
A29: #EVRevolution | B29: {=AVERAGE(_xlfn._xlws.FILTER(Posts!F:F,(Posts!L:L=A29)+(Posts!M:M=A29)+(Posts!N:N=A29)))} -> 2836.3168 | C29: {=AVERAGE(_xlfn._xlws.FILTER(Posts!G:G,(Posts!L:L=A29)+(Posts!M:M=A29)+(Posts!N:N=A29)))} -> 462.66337 | D29: {=AVERAGE(_xlfn._xlws.FILTER(Posts!H:H,(Posts!L:L=A29)+(Posts!M:M=A29)+(Posts!N:N=A29)))} -> 231.61386 | E29: {=AVERAGE(_xlfn._xlws.FILTER(Posts!K:K,(Posts!L:L=A29)+(Posts!M:M=A29)+(Posts!N:N=A29)))} -> 152.78218 | F29: {=AVERAGE(_xlfn._xlws.FILTER(Posts!P:P,(Posts!L:L=A29)+(Posts!M:M=A29)+(Posts!N:N=A29)))} -> 0.15459347
A30: #TeslaCoInnovation | B30: {=AVERAGE(_xlfn._xlws.FILTER(Posts!F:F,(Posts!L:L=A30)+(Posts!M:M=A30)+(Posts!N:N=A30)))} -> 2705.1028 | C30: {=AVERAGE(_xlfn._xlws.FILTER(Posts!G:G,(Posts!L:L=A30)+(Posts!M:M=A30)+(Posts!N:N=A30)))} -> 458.01869 | D30: {=AVERAGE(_xlfn._xlws.FILTER(Posts!H:H,(Posts!L:L=A30)+(Posts!M:M=A30)+(Posts!N:N=A30)))} -> 254.18692 | E30: {=AVERAGE(_xlfn._xlws.FILTER(Posts!K:K,(Posts!L:L=A30)+(Posts!M:M=A30)+(Posts!N:N=A30)))} -> 158.65421 | F30: {=AVERAGE(_xlfn._xlws.FILTER(Posts!P:P,(Posts!L:L=A30)+(Posts!M:M=A30)+(Posts!N:N=A30)))} -> 0.14515321
A31: #FutureOfDriving | B31: {=AVERAGE(_xlfn._xlws.FILTER(Posts!F:F,(Posts!L:L=A31)+(Posts!M:M=A31)+(Posts!N:N=A31)))} -> 2634.7184 | C31: {=AVERAGE(_xlfn._xlws.FILTER(Posts!G:G,(Posts!L:L=A31)+(Posts!M:M=A31)+(Posts!N:N=A31)))} -> 508.63107 | D31: {=AVERAGE(_xlfn._xlws.FILTER(Posts!H:H,(Posts!L:L=A31)+(Posts!M:M=A31)+(Posts!N:N=A31)))} -> 262.50485 | E31: {=AVERAGE(_xlfn._xlws.FILTER(Posts!K:K,(Posts!L:L=A31)+(Posts!M:M=A31)+(Posts!N:N=A31)))} -> 144.03883 | F31: {=AVERAGE(_xlfn._xlws.FILTER(Posts!P:P,(Posts!L:L=A31)+(Posts!M:M=A31)+(Posts!N:N=A31)))} -> 0.14123247
A32: #BetterWithTesla | B32: {=AVERAGE(_xlfn._xlws.FILTER(Posts!F:F,(Posts!L:L=A32)+(Posts!M:M=A32)+(Posts!N:N=A32)))} -> 3451.7143 | C32: {=AVERAGE(_xlfn._xlws.FILTER(Posts!G:G,(Posts!L:L=A32)+(Posts!M:M=A32)+(Posts!N:N=A32)))} -> 540.57143 | D32: {=AVERAGE(_xlfn._xlws.FILTER(Posts!H:H,(Posts!L:L=A32)+(Posts!M:M=A32)+(Posts!N:N=A32)))} -> 151 | E32: {=AVERAGE(_xlfn._xlws.FILTER(Posts!K:K,(Posts!L:L=A32)+(Posts!M:M=A32)+(Posts!N:N=A32)))} -> 114.85714 | F32: {=AVERAGE(_xlfn._xlws.FILTER(Posts!P:P,(Posts!L:L=A32)+(Posts!M:M=A32)+(Posts!N:N=A32)))} -> 0.12589595 | G32: Posts containing the hashtag #EVRevolution achieve the highest average engagement and interaction levels.
A33: #AnytimeIsTeslaTime | B33: {=AVERAGE(_xlfn._xlws.FILTER(Posts!F:F,(Posts!L:L=A33)+(Posts!M:M=A33)+(Posts!N:N=A33)))} -> 2219.6 | C33: {=AVERAGE(_xlfn._xlws.FILTER(Posts!G:G,(Posts!L:L=A33)+(Posts!M:M=A33)+(Posts!N:N=A33)))} -> 423.93333 | D33: {=AVERAGE(_xlfn._xlws.FILTER(Posts!H:H,(Posts!L:L=A33)+(Posts!M:M=A33)+(Posts!N:N=A33)))} -> 257.4 | E33: {=AVERAGE(_xlfn._xlws.FILTER(Posts!K:K,(Posts!L:L=A33)+(Posts!M:M=A33)+(Posts!N:N=A33)))} -> 161.2 | F33: {=AVERAGE(_xlfn._xlws.FILTER(Posts!P:P,(Posts!L:L=A33)+(Posts!M:M=A33)+(Posts!N:N=A33)))} -> 0.11636074
A34: #SmoothLikeNitroTesla | B34: {=AVERAGE(_xlfn._xlws.FILTER(Posts!F:F,(Posts!L:L=A34)+(Posts!M:M=A34)+(Posts!N:N=A34)))} -> 3127.8 | C34: {=AVERAGE(_xlfn._xlws.FILTER(Posts!G:G,(Posts!L:L=A34)+(Posts!M:M=A34)+(Posts!N:N=A34)))} -> 356.2 | D34: {=AVERAGE(_xlfn._xlws.FILTER(Posts!H:H,(Posts!L:L=A34)+(Posts!M:M=A34)+(Posts!N:N=A34)))} -> 283.4 | E34: {=AVERAGE(_xlfn._xlws.FILTER(Posts!K:K,(Posts!L:L=A34)+(Posts!M:M=A34)+(Posts!N:N=A34)))} -> 111.8 | F34: {=AVERAGE(_xlfn._xlws.FILTER(Posts!P:P,(Posts!L:L=A34)+(Posts!M:M=A34)+(Posts!N:N=A34)))} -> 0.11481754
A46: Content Type | B46: Average of Likes | C46: Average of Shares | D46: Average of Comments | E46: Average of Clicks | F46: Average of Engagement Rate
A47: Story | B47: 2706.2609 | C47: 520.76087 | D47: 263.19565 | E47: 131.69565 | F47: 0.18425775
A48: Reel | B48: 2722.234 | C48: 493.6383 | D48: 240.85106 | E48: 152.65957 | F48: 0.15615682
A49: Carousel | B49: 2745.7458 | C49: 448.66102 | D49: 245.89831 | E49: 156.81356 | F49: 0.1481492
A50: Video | B50: 2688.2558 | C50: 488.25581 | D50: 239.04651 | E50: 132.83721 | F50: 0.14814844
A51: Image | B51: 2753.4603 | C51: 470 | D51: 259.55556 | E51: 163.5873 | F51: 0.13687494
A52: Text | B52: 2773.7143 | C52: 445.07143 | D52: 244.88095 | E52: 163.40476 | F52: 0.11750674
A53: Grand Total | B53: 2733.3033 | C53: 476.41667 | D53: 249.50333 | E53: 151.22 | F53: 0.14828272
A55: Recommendation
A57: Since Story content generates the highest engagement, Tesla should prioritize story-based content on platforms where stories are popular, such as Instagram and Facebook.

Sheet Campaign Effectiveness T-5
A3: Campaign_Name | B3: Sum of Impressions | C3: Sum of Likes | D3: Sum of Clicks | E3: Avg Impressions | F3: Avg Likes | G3: Avg Clicks
A4: CybertruckLaunch | B4: 1846272 | C4: 138793 | D4: 6434 | E4: 38464 | F4: 2891.5208 | G4: 134.04167
A5: FSDUpdate | B5: 2266053 | C5: 183346 | D5: 10032 | E5: 33821.687 | F5: 2736.5075 | G5: 149.73134
A6: ModelYCampaign | B6: 1986356 | C6: 159783 | D6: 9872 | E6: 34247.517 | F6: 2754.8793 | G6: 170.2069
A7: SustainabilityDrive | B7: 2464864 | C7: 187909 | D7: 10689 | E7: 34716.394 | F7: 2646.6056 | G7: 150.5493
A8: (blank) | B8: 1830608 | C8: 150160 | D8: 8339 | E8: 32689.429 | F8: 2681.4286 | G8: 148.91071
A9: Grand Total | B9: 10394153 | C9: 819991 | D9: 45366 | E9: 34647.177 | F9: 2733.3033 | G9: 151.22
A30: Average of Engagement Rate | B30: Campaign Period
A31: Campaign_Name | B31: Before | C31: During | D31: No Campaign | E31: Grand Total | F31: Uplift Data
A32: CybertruckLaunch | B32: 0.13530148 | C32: 0.077296913 | E32: 0.12925934 | F32: =C32-B32 -> -0.058004568
A33: FSDUpdate | B33: 0.14108804 | C33: 0.20610363 | E33: 0.14399919 | F33: =C33-B33 -> 0.065015585
A34: ModelYCampaign | B34: 0.13996497 | C34: 0.15063545 | E34: 0.14125279 | F34: =C34-B34 -> 0.010670472
A35: SustainabilityDrive | B35: 0.15710994 | C35: 0.11210141 | E35: 0.15203856 | F35: =C35-B35 -> -0.045008534
A36: (blank) | D36: 0.17223258 | E36: 0.17223258 | F36: =C36-B36 -> 0
A37: Grand Total | B37: 0.14427031 | C37: 0.12852412 | D37: 0.17223258 | E37: 0.14828272
A40: Data Observation
A42: Some posts in the dataset are tagged with campaign names that fall outside the official campaign date ranges provided in the Campaign Metadata sheet. For the purpose of this analysis, the campaign labels assigned in the Posts dataset were used as the primary reference for campaign performance evaluation.
A53: Campaign_Name | B53: Sum of Likes | C53: Sum of Shares | D53: Sum of Comments | E53: Total Engagement | F53: Campaign Budget | G53: ROI (Return on Investment)
A54: CybertruckLaunch | B54: 138793 | C54: 23053 | D54: 12055 | E54: =B54+C54+D54 -> 173901 | F54: =_xlfn.IFNA(_xlfn.XLOOKUP(A54,'Campaign Metadata'!$A$2:$A$5,'Campaign Metadata'!$E$2:$E$5),"") -> 150000 | G54: =E54/F54 -> 1.15934
A55: FSDUpdate | B55: 183346 | C55: 32909 | D55: 16566 | E55: =B55+C55+D55 -> 232821 | F55: =_xlfn.IFNA(_xlfn.XLOOKUP(A55,'Campaign Metadata'!$A$2:$A$5,'Campaign Metadata'!$E$2:$E$5),"") -> 250000 | G55: =E55/F55 -> 0.931284
A56: ModelYCampaign | B56: 159783 | C56: 26553 | D56: 15403 | E56: =B56+C56+D56 -> 201739 | F56: =_xlfn.IFNA(_xlfn.XLOOKUP(A56,'Campaign Metadata'!$A$2:$A$5,'Campaign Metadata'!$E$2:$E$5),"") -> 200000 | G56: =E56/F56 -> 1.008695
A57: SustainabilityDrive | B57: 187909 | C57: 34860 | D57: 17714 | E57: =B57+C57+D57 -> 240483 | F57: =_xlfn.IFNA(_xlfn.XLOOKUP(A57,'Campaign Metadata'!$A$2:$A$5,'Campaign Metadata'!$E$2:$E$5),"") -> 180000 | G57: =E57/F57 -> 1.3360167
A58: (blank) | B58: 150160 | C58: 25550 | D58: 13113 | E58: =B58+C58+D58 -> 188823 | F58: =_xlfn.IFNA(_xlfn.XLOOKUP(A58,'Campaign Metadata'!$A$2:$A$5,'Campaign Metadata'!$E$2:$E$5),"0") -> 0
A59: Grand Total | B59: 819991 | C59: 142925 | D59: 74851
A61: Insight
A63: SustainabilityDrive campaign achieved the highest ROI, generating the highest engagement relative to its marketing budget. This indicates that the campaign was the most efficient in converting advertising spend into audience interaction.
A75: Campaign Period | B75: Sum of Net_Growth
A76: FSDUpdate | B76: 10087
A77: ModelYCampaign | B77: 11092
A78: CybertruckLaunch | B78: 13523
A79: SustainabilityDrive | B79: 16078
A80: No Campaign | B80: 109325
A81: Grand Total | B81: 160105
A84: Insight
A86: The SustainabilityDrive campaign drove the highest follower growth, indicating that sustainability-focused messaging strongly resonates with Tesla’s audience and helps expand the brand’s social media reach.

Sheet Follower Retension Task-6
A3: Sum of Net_Growth | B3: Platform
A4: Week_Start_Date | B4: Facebook | C4: Instagram | D4: Twitter | E4: YouTube | F4: Grand Total
A5: 2024-06-03 | B5: 1002 | C5: 1047 | D5: 415 | E5: 1090 | F5: 3554
A6: 2024-06-10 | B6: 1283 | C6: 517 | D6: 186 | E6: 994 | F6: 2980
A7: 2024-06-17 | B7: 1382 | C7: 893 | D7: 1295 | E7: 337 | F7: 3907
A8: 2024-06-24 | B8: 1670 | C8: 629 | D8: 835 | E8: -123 | F8: 3011
A9: 2024-07-01 | B9: 64 | C9: -219 | D9: 1357 | E9: 91 | F9: 1293
A10: 2024-07-08 | B10: 309 | C10: 1672 | D10: 547 | E10: 514 | F10: 3042
A11: 2024-07-15 | B11: -164 | C11: 1845 | D11: 429 | E11: 160 | F11: 2270
A12: 2024-07-22 | B12: 961 | C12: 159 | D12: 1316 | E12: 317 | F12: 2753
A13: 2024-07-29 | B13: -318 | C13: 541 | D13: 1495 | E13: 475 | F13: 2193
A14: 2024-08-05 | B14: -197 | C14: 352 | D14: 328 | E14: 319 | F14: 802
A15: 2024-08-12 | B15: 1334 | C15: 1325 | D15: 37 | E15: 1032 | F15: 3728
A16: 2024-08-19 | B16: 1058 | C16: 76 | D16: 1665 | E16: 190 | F16: 2989
... A31: 2024-12-02 | B31: 1706 | C31: 1625 | D31: 1173 | E31: 291 | F31: 4795
A32: 2024-12-09 | B32: 1373 | C32: 1119 | D32: 1727 | E32: 573 | F32: 4792 | H32: Insight
A33: 2024-12-16 | B33: 1377 | C33: 1432 | D33: 1359 | E33: 876 | F33: 5044
A34: 2024-12-23 | B34: 730 | C34: 684 | D34: 911 | E34: 1589 | F34: 3914 | H34: The highest follower growth was observed during the week of 2024-12-30, indicating a spike in audience acquisition likely driven by campaign or content performance.
A35: 2024-12-30 | B35: 1776 | C35: 1765 | D35: 1529 | E35: 1460 | F35: 6530
A36: 2025-01-06 | B36: 620 | C36: 903 | D36: 1188 | E36: 846 | F36: 3557
A37: 2025-01-13 | B37: 298 | C37: 1722 | D37: -144 | E37: 901 | F37: 2777
A38: 2025-01-20 | B38: 427 | C38: 1572 | D38: 891 | E38: 724 | F38: 3614
A39: 2025-01-27 | B39: 898 | C39: -166 | D39: 1426 | E39: 1225 | F39: 3383
A40: 2025-02-03 | B40: 748 | C40: 1080 | D40: 569 | E40: -203 | F40: 2194
A41: 2025-02-10 | B41: 912 | C41: 1723 | D41: 1202 | E41: 1444 | F41: 5281
A42: 2025-02-17 | B42: 1590 | C42: 965 | D42: -37 | E42: 1175 | F42: 3693
A43: 2025-02-24 | B43: 1707 | C43: 1375 | D43: 708 | E43: 1016 | F43: 4806
A44: 2025-03-03 | B44: -119 | C44: 1315 | D44: 899 | E44: 315 | F44: 2410
A45: 2025-03-10 | B45: 908 | C45: 212 | D45: 1350 | E45: 1242 | F45: 3712
A46: 2025-03-17 | B46: 1116 | C46: 680 | D46: 861 | E46: 1385 | F46: 4042
... A55: Grand Total | B55: 35557 | C55: 48004 | D55: 41177 | E55: 35367 | F55: 160105
A63: Week_Start_Date | B63: Facebook | C63: Instagram | D63: Twitter | E63: YouTube | F63: Grand Total | G63: 3-Week MA
A64: 2024-06-03 | B64: 1002 | C64: 1047 | D64: 415 | E64: 1090 | F64: 3554
A65: 2024-06-10 | B65: 1283 | C65: 517 | D65: 186 | E65: 994 | F65: 2980
A66: 2024-06-17 | B66: 1382 | C66: 893 | D66: 1295 | E66: 337 | F66: 3907
A67: 2024-06-24 | B67: 1670 | C67: 629 | D67: 835 | E67: -123 | F67: 3011 | G67: =AVERAGE(F64:F66) -> 3480.3333
A68: 2024-07-01 | B68: 64 | C68: -219 | D68: 1357 | E68: 91 | F68: 1293 | G68: =AVERAGE(F65:F67) -> 3299.3333
A69: 2024-07-08 | B69: 309 | C69: 1672 | D69: 547 | E69: 514 | F69: 3042 | G69: =AVERAGE(F66:F68) -> 2737
A70: 2024-07-15 | B70: -164 | C70: 1845 | D70: 429 | E70: 160 | F70: 2270 | G70: =AVERAGE(F67:F69) -> 2448.6667
A71: 2024-07-22 | B71: 961 | C71: 159 | D71: 1316 | E71: 317 | F71: 2753 | G71: =AVERAGE(F68:F70) -> 2201.6667
...

Sheet Posts
A1: Post ID | B1: Platform | C1: Date | D1: Content Type | E1: Post Text | F1: Likes | G1: Shares | H1: Comments | I1: Impressions | J1: Reach | K1: Clicks | L1: Hashtags 1 | M1: Hashtags 2 | N1: Hashtags 3 | O1: Campaign_Name | P1: Engagement Rate | Q1: Unique Hashtags | R1: Hashtag Uses Count | S1: Campaign Start | T1: Campaign End | U1: Campaign Period | V1: Total Engagement
A2: P220 | B2: Instagram | C2: 2024-06-02 | D2: Story | E2: Check out our latest story on instagram! | F2: 84 | G2: 897 | H2: 85 | I2: 588 | J2: 8 | K2: 12 | L2: #EVRevolution | P2: =(F2+G2+H2)/I2 -> 1.8129252 | Q2: {=_xlfn.UNIQUE(_xlfn._xlws.FILTER(_xlfn.VSTACK(L3:L302,M3:M302,N3:N302),_xlfn.VSTACK(L3:L302,M3:M302,N3:N302)<>""))} -> #TeslaCoInnovation | R2: =COUNTIF(L:L,Q2)+COUNTIF(M:M,Q2)+COUNTIF(N:N,Q2) -> 107 | S2: =IFERROR(_xlfn.XLOOKUP(O2,'Campaign Metadata'!$A$2:$A$5,'Campaign Metadata'!$B$2:$B$5),"") | T2: =IFERROR(_xlfn.XLOOKUP(O2,'Campaign Metadata'!$A$2:$A$5,'Campaign Metadata'!$C$2:$C$5),"") | U2: =IF(O2="","No Campaign",IF(AND(C2>=S2,C2<=T2),"During","Before")) -> No Campaign | V2: =F2+G2+H2 -> 1066
A3: P058 | B3: Instagram | C3: 2025-04-15 | D3: Reel | E3: Check out our latest reel on instagram! | F3: 103 | G3: 770 | H3: 19 | I3: 1030 | J3: 410 | K3: 262 | L3: #TeslaCoInnovation | O3: SustainabilityDrive | P3: =(F3+G3+H3)/I3 -> 0.86601942 | Q3: #EVRevolution | R3: =COUNTIF(L:L,Q3)+COUNTIF(M:M,Q3)+COUNTIF(N:N,Q3) -> 102 | S3: =IFERROR(_xlfn.XLOOKUP(O3,'Campaign Metadata'!$A$2:$A$5,'Campaign Metadata'!$B$2:$B$5),"") -> 2025-03-01 | T3: =IFERROR(_xlfn.XLOOKUP(O3,'Campaign Metadata'!$A$2:$A$5,'Campaign Metadata'!$C$2:$C$5),"") -> 2025-03-31 | U3: =IF(O3="","No Campaign",IF(AND(C3>=S3,C3<=T3),"During","Before")) -> Before | V3: =F3+G3+H3 -> 892
A4: P232 | B4: Twitter | C4: 2025-04-29 | D4: Story | E4: Check out our latest story on twitter! | F4: 249 | G4: 592 | H4: 230 | I4: 1494 | J4: 1044 | K4: 201 | L4: #EVRevolution | O4: SustainabilityDrive | P4: =(F4+G4+H4)/I4 -> 0.71686747 | Q4: #FutureOfDriving | R4: =COUNTIF(L:L,Q4)+COUNTIF(M:M,Q4)+COUNTIF(N:N,Q4) -> 103 | S4: =IFERROR(_xlfn.XLOOKUP(O4,'Campaign Metadata'!$A$2:$A$5,'Campaign Metadata'!$B$2:$B$5),"") -> 2025-03-01 | T4: =IFERROR(_xlfn.XLOOKUP(O4,'Campaign Metadata'!$A$2:$A$5,'Campaign Metadata'!$C$2:$C$5),"") -> 2025-03-31 | U4: =IF(O4="","No Campaign",IF(AND(C4>=S4,C4<=T4),"During","Before")) -> Before | V4: =F4+G4+H4 -> 1071
A5: P178 | B5: Instagram | C5: 2024-11-07 | D5: Video | E5: Check out our latest video on instagram! | F5: 129 | G5: 643 | H5: 136 | I5: 1290 | J5: 839 | K5: 238 | L5: #TeslaCoInnovation | O5: SustainabilityDrive | P5: =(F5+G5+H5)/I5 -> 0.70387597 | Q5: #BetterWithTesla | R5: =COUNTIF(L:L,Q5)+COUNTIF(M:M,Q5)+COUNTIF(N:N,Q5) -> 7 | S5: =IFERROR(_xlfn.XLOOKUP(O5,'Campaign Metadata'!$A$2:$A$5,'Campaign Metadata'!$B$2:$B$5),"") -> 2025-03-01 | T5: =IFERROR(_xlfn.XLOOKUP(O5,'Campaign Metadata'!$A$2:$A$5,'Campaign Metadata'!$C$2:$C$5),"") -> 2025-03-31 | U5: =IF(O5="","No Campaign",IF(AND(C5>=S5,C5<=T5),"During","Before")) -> Before | V5: =F5+G5+H5 -> 908
A6: P175 | B6: Instagram | C6: 2025-01-17 | D6: Reel | E6: Check out our latest reel on instagram! | F6: 142 | G6: 784 | H6: 183 | I6: 1704 | J6: 995 | K6: 154 | L6: #FutureOfDriving | O6: SustainabilityDrive | P6: =(F6+G6+H6)/I6 -> 0.6508216 | Q6: #AnytimeIsTeslaTime | R6: =COUNTIF(L:L,Q6)+COUNTIF(M:M,Q6)+COUNTIF(N:N,Q6) -> 15 | S6: =IFERROR(_xlfn.XLOOKUP(O6,'Campaign Metadata'!$A$2:$A$5,'Campaign Metadata'!$B$2:$B$5),"") -> 2025-03-01 | T6: =IFERROR(_xlfn.XLOOKUP(O6,'Campaign Metadata'!$A$2:$A$5,'Campaign Metadata'!$C$2:$C$5),"") -> 2025-03-31 | U6: =IF(O6="","No Campaign",IF(AND(C6>=S6,C6<=T6),"During","Before")) -> Before | V6: =F6+G6+H6 -> 1109
A7: P062 | B7: Twitter | C7: 2024-11-22 | D7: Carousel | E7: Check out our latest carousel on twitter! | F7: 53 | G7: 81 | H7: 379 | I7: 954 | J7: 7 | K7: 148 | L7: #TeslaCoInnovation | O7: FSDUpdate | P7: =(F7+G7+H7)/I7 -> 0.53773585 | Q7: #SmoothLikeNitroTesla | R7: =COUNTIF(L:L,Q7)+COUNTIF(M:M,Q7)+COUNTIF(N:N,Q7) -> 5 | S7: =IFERROR(_xlfn.XLOOKUP(O7,'Campaign Metadata'!$A$2:$A$5,'Campaign Metadata'!$B$2:$B$5),"") -> 2024-12-25 | T7: =IFERROR(_xlfn.XLOOKUP(O7,'Campaign Metadata'!$A$2:$A$5,'Campaign Metadata'!$C$2:$C$5),"") -> 2025-01-10 | U7: =IF(O7="","No Campaign",IF(AND(C7>=S7,C7<=T7),"During","Before")) -> Before | V7: =F7+G7+H7 -> 513
A8: P264 | B8: Twitter | C8: 2025-01-30 | D8: Image | E8: Check out our latest image on twitter! | F8: 59 | G8: 163 | H8: 93 | I8: 590 | J8: 475 | K8: 293 | L8: #TeslaCoInnovation | O8: ModelYCampaign | P8: =(F8+G8+H8)/I8 -> 0.53389831 | S8: =IFERROR(_xlfn.XLOOKUP(O8,'Campaign Metadata'!$A$2:$A$5,'Campaign Metadata'!$B$2:$B$5),"") -> 2024-10-01 | T8: =IFERROR(_xlfn.XLOOKUP(O8,'Campaign Metadata'!$A$2:$A$5,'Campaign Metadata'!$C$2:$C$5),"") -> 2024-10-31 | U8: =IF(O8="","No Campaign",IF(AND(C8>=S8,C8<=T8),"During","Before")) -> Before | V8: =F8+G8+H8 -> 315
A9: P143 | B9: YouTube | C9: 2024-10-02 | D9: Carousel | E9: Check out our latest carousel on youtube! | F9: 80 | G9: 362 | H9: 80 | I9: 1040 | J9: 349 | K9: 117 | L9: #TeslaCoInnovation | O9: FSDUpdate | P9: =(F9+G9+H9)/I9 -> 0.50192308 | S9: =IFERROR(_xlfn.XLOOKUP(O9,'Campaign Metadata'!$A$2:$A$5,'Campaign Metadata'!$B$2:$B$5),"") -> 2024-12-25 | T9: =IFERROR(_xlfn.XLOOKUP(O9,'Campaign Metadata'!$A$2:$A$5,'Campaign Metadata'!$C$2:$C$5),"") -> 2025-01-10 | U9: =IF(O9="","No Campaign",IF(AND(C9>=S9,C9<=T9),"During","Before")) -> Before | V9: =F9+G9+H9 -> 522
A10: P210 | B10: YouTube | C10: 2025-02-19 | D10: Image | E10: Check out our latest image on youtube! | F10: 257 | G10: 966 | H10: 398 | I10: 3341 | J10: 2753 | K10: 287 | L10: #FutureOfDriving | O10: CybertruckLaunch | P10: =(F10+G10+H10)/I10 -> 0.48518408 | S10: =IFERROR(_xlfn.XLOOKUP(O10,'Campaign Metadata'!$A$2:$A$5,'Campaign Metadata'!$B$2:$B$5),"") -> 2024-06-15 | T10: =IFERROR(_xlfn.XLOOKUP(O10,'Campaign Metadata'!$A$2:$A$5,'Campaign Metadata'!$C$2:$C$5),"") -> 2024-07-15 | U10: =IF(O10="","No Campaign",IF(AND(C10>=S10,C10<=T10),"During","Before")) -> Before | V10: =F10+G10+H10 -> 1621
A11: P070 | B11: Facebook | C11: 2025-04-02 | D11: Video | E11: Check out our latest video on facebook! | F11: 199 | G11: 772 | H11: 400 | I11: 3582 | J11: 2988 | K11: 43 | L11: #TeslaCoInnovation | P11: =(F11+G11+H11)/I11 -> 0.38274707 | S11: =IFERROR(_xlfn.XLOOKUP(O11,'Campaign Metadata'!$A$2:$A$5,'Campaign Metadata'!$B$2:$B$5),"") | T11: =IFERROR(_xlfn.XLOOKUP(O11,'Campaign Metadata'!$A$2:$A$5,'Campaign Metadata'!$C$2:$C$5),"") | U11: =IF(O11="","No Campaign",IF(AND(C11>=S11,C11<=T11),"During","Before")) -> No Campaign | V11: =F11+G11+H11 -> 1371
A12: P214 | B12: Instagram | C12: 2024-12-23 | D12: Image | E12: Check out our latest image on instagram! | F12: 521 | G12: 746 | H12: 315 | I12: 4168 | J12: 3399 | K12: 282 | L12: #FutureOfDriving | O12: ModelYCampaign | P12: =(F12+G12+H12)/I12 -> 0.37955854 | S12: =IFERROR(_xlfn.XLOOKUP(O12,'Campaign Metadata'!$A$2:$A$5,'Campaign Metadata'!$B$2:$B$5),"") -> 2024-10-01 | T12: =IFERROR(_xlfn.XLOOKUP(O12,'Campaign Metadata'!$A$2:$A$5,'Campaign Metadata'!$C$2:$C$5),"") -> 2024-10-31 | U12: =IF(O12="","No Campaign",IF(AND(C12>=S12,C12<=T12),"During","Before")) -> Before | V12: =F12+G12+H12 -> 1582
A13: P053 | B13: YouTube | C13: 2025-02-24 | D13: Carousel | E13: Check out our latest carousel on youtube! | F13: 804 | G13: 639 | H13: 43 | I13: 4020 | J13: 3144 | K13: 11 | L13: #EVRevolution | M13: #BetterWithTesla | P13: =(F13+G13+H13)/I13 -> 0.36965174 | S13: =IFERROR(_xlfn.XLOOKUP(O13,'Campaign Metadata'!$A$2:$A$5,'Campaign Metadata'!$B$2:$B$5),"") | T13: =IFERROR(_xlfn.XLOOKUP(O13,'Campaign Metadata'!$A$2:$A$5,'Campaign Metadata'!$C$2:$C$5),"") | U13: =IF(O13="","No Campaign",IF(AND(C13>=S13,C13<=T13),"During","Before")) -> No Campaign | V13: =F13+G13+H13 -> 1486
A14: P102 | B14: Twitter | C14: 2024-09-18 | D14: Reel | E14: Check out our latest reel on twitter! | F14: 1000 | G14: 978 | H14: 162 | I14: 6000 | J14: 5221 | K14: 223 | L14: #EVRevolution | O14: ModelYCampaign | P14: =(F14+G14+H14)/I14 -> 0.35666667 | S14: =IFERROR(_xlfn.XLOOKUP(O14,'Campaign Metadata'!$A$2:$A$5,'Campaign Metadata'!$B$2:$B$5),"") -> 2024-10-01 | T14: =IFERROR(_xlfn.XLOOKUP(O14,'Campaign Metadata'!$A$2:$A$5,'Campaign Metadata'!$C$2:$C$5),"") -> 2024-10-31 | U14: =IF(O14="","No Campaign",IF(AND(C14>=S14,C14<=T14),"During","Before")) -> Before | V14: =F14+G14+H14 -> 2140
A15: P124 | B15: YouTube | C15: 2025-04-06 | D15: Carousel | E15: Check out our latest carousel on youtube! | F15: 736 | G15: 771 | H15: 225 | I15: 5152 | J15: 4706 | K15: 19 | L15: #EVRevolution | O15: CybertruckLaunch | P15: =(F15+G15+H15)/I15 -> 0.33618012 | S15: =IFERROR(_xlfn.XLOOKUP(O15,'Campaign Metadata'!$A$2:$A$5,'Campaign Metadata'!$B$2:$B$5),"") -> 2024-06-15 | T15: =IFERROR(_xlfn.XLOOKUP(O15,'Campaign Metadata'!$A$2:$A$5,'Campaign Metadata'!$C$2:$C$5),"") -> 2024-07-15 | U15: =IF(O15="","No Campaign",IF(AND(C15>=S15,C15<=T15),"During","Before")) -> Before | V15: =F15+G15+H15 -> 1732
A16: P121 | B16: Instagram | C16: 2024-07-29 | D16: Story | E16: Check out our latest story on instagram! | F16: 498 | G16: 701 | H16: 412 | I16: 4980 | J16: 4185 | K16: 185 | L16: #FutureOfDriving | P16: =(F16+G16+H16)/I16 -> 0.32349398 | S16: =IFERROR(_xlfn.XLOOKUP(O16,'Campaign Metadata'!$A$2:$A$5,'Campaign Metadata'!$B$2:$B$5),"") | T16: =IFERROR(_xlfn.XLOOKUP(O16,'Campaign Metadata'!$A$2:$A$5,'Campaign Metadata'!$C$2:$C$5),"") | U16: =IF(O16="","No Campaign",IF(AND(C16>=S16,C16<=T16),"During","Before")) -> No Campaign | V16: =F16+G16+H16 -> 1611
A17: P224 | B17: Facebook | C17: 2025-05-13 | D17: Image | E17: Check out our latest image on facebook! | F17: 602 | G17: 594 | H17: 156 | I17: 4214 | J17: 3363 | K17: 164 | L17: #TeslaCoInnovation | O17: FSDUpdate | P17: =(F17+G17+H17)/I17 -> 0.32083531 | S17: =IFERROR(_xlfn.XLOOKUP(O17,'Campaign Metadata'!$A$2:$A$5,'Campaign Metadata'!$B$2:$B$5),"") -> 2024-12-25 | T17: =IFERROR(_xlfn.XLOOKUP(O17,'Campaign Metadata'!$A$2:$A$5,'Campaign Metadata'!$C$2:$C$5),"") -> 2025-01-10 | U17: =IF(O17="","No Campaign",IF(AND(C17>=S17,C17<=T17),"During","Before")) -> Before | V17: =F17+G17+H17 -> 1352
A18: P154 | B18: Instagram | C18: 2024-10-09 | D18: Carousel | E18: Check out our latest carousel on instagram! | F18: 985 | G18: 932 | H18: 287 | I18: 6895 | J18: 6757 | K18: 64 | L18: #FutureOfDriving | O18: SustainabilityDrive | P18: =(F18+G18+H18)/I18 -> 0.31965192 | S18: =IFERROR(_xlfn.XLOOKUP(O18,'Campaign Metadata'!$A$2:$A$5,'Campaign Metadata'!$B$2:$B$5),"") -> 2025-03-01 | T18: =IFERROR(_xlfn.XLOOKUP(O18,'Campaign Metadata'!$A$2:$A$5,'Campaign Metadata'!$C$2:$C$5),"") -> 2025-03-31 | U18: =IF(O18="","No Campaign",IF(AND(C18>=S18,C18<=T18),"During","Before")) -> Before | V18: =F18+G18+H18 -> 2204
A19: P119 | B19: Instagram | C19: 2025-02-07 | D19: Reel | E19: Check out our latest reel on instagram! | F19: 1970 | G19: 675 | H19: 478 | I19: 9850 | J19: 8924 | K19: 117 | L19: #FutureOfDriving | P19: =(F19+G19+H19)/I19 -> 0.31705584 | S19: =IFERROR(_xlfn.XLOOKUP(O19,'Campaign Metadata'!$A$2:$A$5,'Campaign Metadata'!$B$2:$B$5),"") | T19: =IFERROR(_xlfn.XLOOKUP(O19,'Campaign Metadata'!$A$2:$A$5,'Campaign Metadata'!$C$2:$C$5),"") | U19: =IF(O19="","No Campaign",IF(AND(C19>=S19,C19<=T19),"During","Before")) -> No Campaign | V19: =F19+G19+H19 -> 3123
A20: P287 | B20: Instagram | C20: 2024-08-15 | D20: Reel | E20: Check out our latest reel on instagram! | F20: 1164 | G20: 616 | H20: 324 | I20: 6984 | J20: 6636 | K20: 82 | L20: #EVRevolution | O20: CybertruckLaunch | P20: =(F20+G20+H20)/I20 -> 0.30126002 | S20: =IFERROR(_xlfn.XLOOKUP(O20,'Campaign Metadata'!$A$2:$A$5,'Campaign Metadata'!$B$2:$B$5),"") -> 2024-06-15 | T20: =IFERROR(_xlfn.XLOOKUP(O20,'Campaign Metadata'!$A$2:$A$5,'Campaign Metadata'!$C$2:$C$5),"") -> 2024-07-15 | U20: =IF(O20="","No Campaign",IF(AND(C20>=S20,C20<=T20),"During","Before")) -> Before | V20: =F20+G20+H20 -> 2104
A21: P204 | B21: Instagram | C21: 2025-01-01 | D21: Carousel | E21: Check out our latest carousel on instagram! | F21: 2234 | G21: 653 | H21: 432 | I21: 11170 | J21: 10569 | K21: 198 | L21: #FutureOfDriving | O21: FSDUpdate | P21: =(F21+G21+H21)/I21 -> 0.29713518 | S21: =IFERROR(_xlfn.XLOOKUP(O21,'Campaign Metadata'!$A$2:$A$5,'Campaign Metadata'!$B$2:$B$5),"") -> 2024-12-25 | T21: =IFERROR(_xlfn.XLOOKUP(O21,'Campaign Metadata'!$A$2:$A$5,'Campaign Metadata'!$C$2:$C$5),"") -> 2025-01-10 | U21: =IF(O21="","No Campaign",IF(AND(C21>=S21,C21<=T21),"During","Before")) -> During | V21: =F21+G21+H21 -> 3319
A22: P066 | B22: Twitter | C22: 2024-07-26 | D22: Carousel | E22: Check out our latest carousel on twitter! | F22: 432 | G22: 171 | H22: 280 | I22: 3024 | J22: 2285 | K22: 184 | L22: #EVRevolution | O22: CybertruckLaunch | P22: =(F22+G22+H22)/I22 -> 0.29199735 | S22: =IFERROR(_xlfn.XLOOKUP(O22,'Campaign Metadata'!$A$2:$A$5,'Campaign Metadata'!$B$2:$B$5),"") -> 2024-06-15 | T22: =IFERROR(_xlfn.XLOOKUP(O22,'Campaign Metadata'!$A$2:$A$5,'Campaign Metadata'!$C$2:$C$5),"") -> 2024-07-15 | U22: =IF(O22="","No Campaign",IF(AND(C22>=S22,C22<=T22),"During","Before")) -> Before | V22: =F22+G22+H22 -> 883
A23: P183 | B23: Instagram | C23: 2024-12-17 | D23: Story | E23: Check out our latest story on instagram! | F23: 360 | G23: 590 | H23: 393 | I23: 4680 | J23: 4322 | K23: 208 | L23: #FutureOfDriving | O23: ModelYCampaign | P23: =(F23+G23+H23)/I23 -> 0.28696581 | S23: =IFERROR(_xlfn.XLOOKUP(O23,'Campaign Metadata'!$A$2:$A$5,'Campaign Metadata'!$B$2:$B$5),"") -> 2024-10-01 | T23: =IFERROR(_xlfn.XLOOKUP(O23,'Campaign Metadata'!$A$2:$A$5,'Campaign Metadata'!$C$2:$C$5),"") -> 2024-10-31 | U23: =IF(O23="","No Campaign",IF(AND(C23>=S23,C23<=T23),"During","Before")) -> Before | V23: =F23+G23+H23 -> 1343
B24: Instagram | C24: 2024-12-16 | D24: Text | E24: Check out our latest text on instagram! | F24: 438 | G24: 153 | H24: 275 | I24: 3066 | J24: 2701 | K24: 282 | L24: #TeslaCoInnovation | O24: ModelYCampaign | P24: =(F24+G24+H24)/I24 -> 0.28245271 | S24: =IFERROR(_xlfn.XLOOKUP(O24,'Campaign Metadata'!$A$2:$A$5,'Campaign Metadata'!$B$2:$B$5),"") -> 2024-10-01 | T24: =IFERROR(_xlfn.XLOOKUP(O24,'Campaign Metadata'!$A$2:$A$5,'Campaign Metadata'!$C$2:$C$5),"") -> 2024-10-31 | U24: =IF(O24="","No Campaign",IF(AND(C24>=S24,C24<=T24),"During","Before")) -> Before | V24: =F24+G24+H24 -> 866
A25: P093 | B25: Instagram | C25: 2024-12-11 | D25: Video | E25: Check out our latest video on instagram! | F25: 1431 | G25: 951 | H25: 26 | I25: 8586 | J25: 8396 | K25: 150 | L25: #EVRevolution | O25: FSDUpdate | P25: =(F25+G25+H25)/I25 -> 0.28045656 | S25: =IFERROR(_xlfn.XLOOKUP(O25,'Campaign Metadata'!$A$2:$A$5,'Campaign Metadata'!$B$2:$B$5),"") -> 2024-12-25 | T25: =IFERROR(_xlfn.XLOOKUP(O25,'Campaign Metadata'!$A$2:$A$5,'Campaign Metadata'!$C$2:$C$5),"") -> 2025-01-10 | U25: =IF(O25="","No Campaign",IF(AND(C25>=S25,C25<=T25),"During","Before")) -> Before | V25: =F25+G25+H25 -> 2408
A26: P263 | B26: Instagram | C26: 2024-08-20 | D26: Reel | E26: Check out our latest reel on instagram! | F26: 2603 | G26: 690 | H26: 205 | I26: 13015 | J26: 12130 | K26: 20 | L26: #FutureOfDriving | O26: ModelYCampaign | P26: =(F26+G26+H26)/I26 -> 0.26876681 | S26: =IFERROR(_xlfn.XLOOKUP(O26,'Campaign Metadata'!$A$2:$A$5,'Campaign Metadata'!$B$2:$B$5),"") -> 2024-10-01 | T26: =IFERROR(_xlfn.XLOOKUP(O26,'Campaign Metadata'!$A$2:$A$5,'Campaign Metadata'!$C$2:$C$5),"") -> 2024-10-31 | U26: =IF(O26="","No Campaign",IF(AND(C26>=S26,C26<=T26),"During","Before")) -> Before | V26: =F26+G26+H26 -> 3498
A27: P248 | B27: Facebook | C27: 2025-02-02 | D27: Story | E27: Check out our latest story on facebook! | F27: 886 | G27: 126 | H27: 153 | I27: 4430 | J27: 4037 | K27: 212 | L27: #EVRevolution | P27: =(F27+G27+H27)/I27 -> 0.26297968 | S27: =IFERROR(_xlfn.XLOOKUP(O27,'Campaign Metadata'!$A$2:$A$5,'Campaign Metadata'!$B$2:$B$5),"") | T27: =IFERROR(_xlfn.XLOOKUP(O27,'Campaign Metadata'!$A$2:$A$5,'Campaign Metadata'!$C$2:$C$5),"") | U27: =IF(O27="","No Campaign",IF(AND(C27>=S27,C27<=T27),"During","Before")) -> No Campaign | V27: =F27+G27+H27 -> 1165
A28: P244 | B28: YouTube | C28: 2024-10-25 | D28: Video | E28: Check out our latest video on youtube! | F28: 4661 | G28: 935 | H28: 433 | I28: 23305 | J28: 22583 | K28: 63 | L28: #FutureOfDriving | O28: FSDUpdate | P28: =(F28+G28+H28)/I28 -> 0.25869985 | S28: =IFERROR(_xlfn.XLOOKUP(O28,'Campaign Metadata'!$A$2:$A$5,'Campaign Metadata'!$B$2:$B$5),"") -> 2024-12-25 | T28: =IFERROR(_xlfn.XLOOKUP(O28,'Campaign Metadata'!$A$2:$A$5,'Campaign Metadata'!$C$2:$C$5),"") -> 2025-01-10 | U28: =IF(O28="","No Campaign",IF(AND(C28>=S28,C28<=T28),"During","Before")) -> Before | V28: =F28+G28+H28 -> 6029
A29: P259 | B29: Facebook | C29: 2025-02-10 | D29: Text | E29: Check out our latest text on facebook! | F29: 562 | G29: 158 | H29: 149 | I29: 3372 | J29: 2940 | K29: 93 | L29: #TeslaCoInnovation | O29: CybertruckLaunch | P29: =(F29+G29+H29)/I29 -> 0.25771056 | S29: =IFERROR(_xlfn.XLOOKUP(O29,'Campaign Metadata'!$A$2:$A$5,'Campaign Metadata'!$B$2:$B$5),"") -> 2024-06-15 | T29: =IFERROR(_xlfn.XLOOKUP(O29,'Campaign Metadata'!$A$2:$A$5,'Campaign Metadata'!$C$2:$C$5),"") -> 2024-07-15 | U29: =IF(O29="","No Campaign",IF(AND(C29>=S29,C29<=T29),"During","Before")) -> Before | V29: =F29+G29+H29 -> 869
A30: P219 | B30: Twitter | C30: 2025-01-28 | D30: Reel | E30: Check out our latest reel on twitter! | F30: 1188 | G30: 470 | H30: 174 | I30: 7128 | J30: 6145 | K30: 270 | L30: #TeslaCoInnovation | O30: SustainabilityDrive | P30: =(F30+G30+H30)/I30 -> 0.25701459 | S30: =IFERROR(_xlfn.XLOOKUP(O30,'Campaign Metadata'!$A$2:$A$5,'Campaign Metadata'!$B$2:$B$5),"") -> 2025-03-01 | T30: =IFERROR(_xlfn.XLOOKUP(O30,'Campaign Metadata'!$A$2:$A$5,'Campaign Metadata'!$C$2:$C$5),"") -> 2025-03-31 | U30: =IF(O30="","No Campaign",IF(AND(C30>=S30,C30<=T30),"During","Before")) -> Before | V30: =F30+G30+H30 -> 1832
A31: P226 | B31: Instagram | C31: 2024-08-07 | D31: Carousel | E31: Check out our latest carousel on instagram! | F31: 1741 | G31: 164 | H31: 318 | I31: 8705 | J31: 8272 | K31: 121 | L31: #TeslaCoInnovation | P31: =(F31+G31+H31)/I31 -> 0.25537048 | S31: =IFERROR(_xlfn.XLOOKUP(O31,'Campaign Metadata'!$A$2:$A$5,'Campaign Metadata'!$B$2:$B$5),"") | T31: =IFERROR(_xlfn.XLOOKUP(O31,'Campaign Metadata'!$A$2:$A$5,'Campaign Metadata'!$C$2:$C$5),"") | U31: =IF(O31="","No Campaign",IF(AND(C31>=S31,C31<=T31),"During","Before")) -> No Campaign | V31: =F31+G31+H31 -> 2223
A32: P265 | B32: Twitter | C32: 2025-02-20 | D32: Carousel | E32: Check out our latest carousel on twitter! | F32: 1877 | G32: 745 | H32: 225 | I32: 11262 | J32: 10967 | K32: 41 | L32: #EVRevolution | O32: SustainabilityDrive | P32: =(F32+G32+H32)/I32 -> 0.25279702 | S32: =IFERROR(_xlfn.XLOOKUP(O32,'Campaign Metadata'!$A$2:$A$5,'Campaign Metadata'!$B$2:$B$5),"") -> 2025-03-01 | T32: =IFERROR(_xlfn.XLOOKUP(O32,'Campaign Metadata'!$A$2:$A$5,'Campaign Metadata'!$C$2:$C$5),"") -> 2025-03-31 | U32: =IF(O32="","No Campaign",IF(AND(C32>=S32,C32<=T32),"During","Before")) -> Before | V32: =F32+G32+H32 -> 2847
A33: P239 | B33: YouTube | C33: 2025-02-24 | D33: Text | E33: Check out our latest text on youtube! | F33: 4188 | G33: 942 | H33: 118 | I33: 20940 | J33: 20471 | K33: 102 | L33: #FutureOfDriving | P33: =(F33+G33+H33)/I33 -> 0.25062082 | S33: =IFERROR(_xlfn.XLOOKUP(O33,'Campaign Metadata'!$A$2:$A$5,'Campaign Metadata'!$B$2:$B$5),"") | T33: =IFERROR(_xlfn.XLOOKUP(O33,'Campaign Metadata'!$A$2:$A$5,'Campaign Metadata'!$C$2:$C$5),"") | U33: =IF(O33="","No Campaign",IF(AND(C33>=S33,C33<=T33),"During","Before")) -> No Campaign | V33: =F33+G33+H33 -> 5248
A34: P277 | B34: Facebook | C34: 2025-04-06 | D34: Image | E34: Check out our latest image on facebook! | F34: 4236 | G34: 711 | H34: 298 | I34: 21180 | J34: 20516 | K34: 238 | L34: #FutureOfDriving | O34: CybertruckLaunch | P34: =(F34+G34+H34)/I34 -> 0.24763928 | S34: =IFERROR(_xlfn.XLOOKUP(O34,'Campaign Metadata'!$A$2:$A$5,'Campaign Metadata'!$B$2:$B$5),"") -> 2024-06-15 | T34: =IFERROR(_xlfn.XLOOKUP(O34,'Campaign Metadata'!$A$2:$A$5,'Campaign Metadata'!$C$2:$C$5),"") -> 2024-07-15 | U34: =IF(O34="","No Campaign",IF(AND(C34>=S34,C34<=T34),"During","Before")) -> Before | V34: =F34+G34+H34 -> 5245
A35: P297 | B35: Twitter | C35: 2024-12-24 | D35: Text | E35: Check out our latest text on twitter! | F35: 2166 | G35: 354 | H35: 117 | I35: 10830 | J35: 10245 | K35: 24 | L35: #EVRevolution | O35: SustainabilityDrive | P35: =(F35+G35+H35)/I35 -> 0.2434903 | S35: =IFERROR(_xlfn.XLOOKUP(O35,'Campaign Metadata'!$A$2:$A$5,'Campaign Metadata'!$B$2:$B$5),"") -> 2025-03-01 | T35: =IFERROR(_xlfn.XLOOKUP(O35,'Campaign Metadata'!$A$2:$A$5,'Campaign Metadata'!$C$2:$C$5),"") -> 2025-03-31 | U35: =IF(O35="","No Campaign",IF(AND(C35>=S35,C35<=T35),"During","Before")) -> Before | V35: =F35+G35+H35 -> 2637
A36: P181 | B36: YouTube | C36: 2025-03-21 | D36: Image | E36: Check out our latest image on youtube! | F36: 606 | G36: 789 | H36: 470 | I36: 7878 | J36: 7389 | K36: 239 | L36: #EVRevolution | O36: FSDUpdate | P36: =(F36+G36+H36)/I36 -> 0.23673521 | S36: =IFERROR(_xlfn.XLOOKUP(O36,'Campaign Metadata'!$A$2:$A$5,'Campaign Metadata'!$B$2:$B$5),"") -> 2024-12-25 | T36: =IFERROR(_xlfn.XLOOKUP(O36,'Campaign Metadata'!$A$2:$A$5,'Campaign Metadata'!$C$2:$C$5),"") -> 2025-01-10 | U36: =IF(O36="","No Campaign",IF(AND(C36>=S36,C36<=T36),"During","Before")) -> Before | V36: =F36+G36+H36 -> 1865
A37: P246 | B37: Facebook | C37: 2024-10-11 | D37: Image | E37: Check out our latest image on facebook! | F37: 400 | G37: 680 | H37: 434 | I37: 6400 | J37: 5472 | K37: 160 | L37: #FutureOfDriving | O37: ModelYCampaign | P37: =(F37+G37+H37)/I37 -> 0.2365625 | S37: =IFERROR(_xlfn.XLOOKUP(O37,'Campaign Metadata'!$A$2:$A$5,'Campaign Metadata'!$B$2:$B$5),"") -> 2024-10-01 | T37: =IFERROR(_xlfn.XLOOKUP(O37,'Campaign Metadata'!$A$2:$A$5,'Campaign Metadata'!$C$2:$C$5),"") -> 2024-10-31 | U37: =IF(O37="","No Campaign",IF(AND(C37>=S37,C37<=T37),"During","Before")) -> During | V37: =F37+G37+H37 -> 1514
A38: P123 | B38: Instagram | C38: 2024-06-14 | D38: Story | E38: Check out our latest story on instagram! | F38: 4363 | G38: 649 | H38: 140 | I38: 21815 | J38: 21481 | K38: 157 | L38: #EVRevolution | O38: CybertruckLaunch | P38: =(F38+G38+H38)/I38 -> 0.23616777 | S38: =IFERROR(_xlfn.XLOOKUP(O38,'Campaign Metadata'!$A$2:$A$5,'Campaign Metadata'!$B$2:$B$5),"") -> 2024-06-15 | T38: =IFERROR(_xlfn.XLOOKUP(O38,'Campaign Metadata'!$A$2:$A$5,'Campaign Metadata'!$C$2:$C$5),"") -> 2024-07-15 | U38: =IF(O38="","No Campaign",IF(AND(C38>=S38,C38<=T38),"During","Before")) -> Before | V38: =F38+G38+H38 -> 5152
A39: P120 | B39: Facebook | C39: 2024-10-21 | D39: Story | E39: Check out our latest story on facebook! | F39: 780 | G39: 928 | H39: 301 | I39: 8580 | J39: 8081 | K39: 91 | L39: #EVRevolution | O39: FSDUpdate | P39: =(F39+G39+H39)/I39 -> 0.23414918 | S39: =IFERROR(_xlfn.XLOOKUP(O39,'Campaign Metadata'!$A$2:$A$5,'Campaign Metadata'!$B$2:$B$5),"") -> 2024-12-25 | T39: =IFERROR(_xlfn.XLOOKUP(O39,'Campaign Metadata'!$A$2:$A$5,'Campaign Metadata'!$C$2:$C$5),"") -> 2025-01-10 | U39: =IF(O39="","No Campaign",IF(AND(C39>=S39,C39<=T39),"During","Before")) -> Before | V39: =F39+G39+H39 -> 2009
A40: P141 | B40: Twitter | C40: 2024-08-31 | D40: Image | E40: Check out our latest image on twitter! | F40: 3170 | G40: 857 | H40: 379 | I40: 19020 | J40: 18559 | K40: 240 | L40: #FutureOfDriving | P40: =(F40+G40+H40)/I40 -> 0.23165089 | S40: =IFERROR(_xlfn.XLOOKUP(O40,'Campaign Metadata'!$A$2:$A$5,'Campaign Metadata'!$B$2:$B$5),"") | T40: =IFERROR(_xlfn.XLOOKUP(O40,'Campaign Metadata'!$A$2:$A$5,'Campaign Metadata'!$C$2:$C$5),"") | U40: =IF(O40="","No Campaign",IF(AND(C40>=S40,C40<=T40),"During","Before")) -> No Campaign | V40: =F40+G40+H40 -> 4406
...

Sheet Engagement Summary
A1: Week_Start_Date | B1: Platform | C1: New_Followers | D1: Unfollows | E1: Total_Followers | F1: Engagement_Rate | G1: Ad_Spend | H1: Net_Growth | I1: Campaign Period | J1: Growth Rate
A2: 2024-06-03 | B2: Instagram | C2: 1135 | D2: 88 | E2: 344084 | F2: 8.06 | G2: 5904 | H2: =C2-D2 -> 1047 | I2: =IF(AND(A2>='Campaign Metadata'!$B$2,A2<='Campaign Metadata'!$C$2),"CybertruckLaunch", IF(AND(A2>='Campaign Metadata'!$B$3,A2<='Campaign Metadata'!$C$3),"ModelYCampaign", IF(AND(A2>='Campaign Metadata'!$B$4,A2<='Campaign Metadata'!$C$4),"FSDUpdate", IF(AND(A2>='Campaign Metadata'!$B$5,A2<='Campaign Metadata'!$C$5),"SustainabilityDrive","No Campaign")))) -> No Campaign | J2: =(C2-D2)/E2 -> 0.0030428616
A3: 2024-06-03 | B3: Facebook | C3: 1312 | D3: 310 | E3: 42654 | F3: 4.98 | G3: 9566 | H3: =C3-D3 -> 1002 | I3: =IF(AND(A3>='Campaign Metadata'!$B$2,A3<='Campaign Metadata'!$C$2),"CybertruckLaunch", IF(AND(A3>='Campaign Metadata'!$B$3,A3<='Campaign Metadata'!$C$3),"ModelYCampaign", IF(AND(A3>='Campaign Metadata'!$B$4,A3<='Campaign Metadata'!$C$4),"FSDUpdate", IF(AND(A3>='Campaign Metadata'!$B$5,A3<='Campaign Metadata'!$C$5),"SustainabilityDrive","No Campaign")))) -> No Campaign | J3: =(C3-D3)/E3 -> 0.023491349
A4: 2024-06-03 | B4: Twitter | C4: 584 | D4: 169 | E4: 146834 | F4: 8.31 | G4: 26752 | H4: =C4-D4 -> 415 | I4: =IF(AND(A4>='Campaign Metadata'!$B$2,A4<='Campaign Metadata'!$C$2),"CybertruckLaunch", IF(AND(A4>='Campaign Metadata'!$B$3,A4<='Campaign Metadata'!$C$3),"ModelYCampaign", IF(AND(A4>='Campaign Metadata'!$B$4,A4<='Campaign Metadata'!$C$4),"FSDUpdate", IF(AND(A4>='Campaign Metadata'!$B$5,A4<='Campaign Metadata'!$C$5),"SustainabilityDrive","No Campaign")))) -> No Campaign | J4: =(C4-D4)/E4 -> 0.0028263209
A5: 2024-06-03 | B5: YouTube | C5: 1535 | D5: 445 | E5: 395536 | F5: 4.11 | G5: 30671 | H5: =C5-D5 -> 1090 | I5: =IF(AND(A5>='Campaign Metadata'!$B$2,A5<='Campaign Metadata'!$C$2),"CybertruckLaunch", IF(AND(A5>='Campaign Metadata'!$B$3,A5<='Campaign Metadata'!$C$3),"ModelYCampaign", IF(AND(A5>='Campaign Metadata'!$B$4,A5<='Campaign Metadata'!$C$4),"FSDUpdate", IF(AND(A5>='Campaign Metadata'!$B$5,A5<='Campaign Metadata'!$C$5),"SustainabilityDrive","No Campaign")))) -> No Campaign | J5: =(C5-D5)/E5 -> 0.0027557542
A6: 2024-06-10 | B6: Instagram | C6: 656 | D6: 139 | E6: 49157 | F6: 9.05 | G6: 9920 | H6: =C6-D6 -> 517 | I6: =IF(AND(A6>='Campaign Metadata'!$B$2,A6<='Campaign Metadata'!$C$2),"CybertruckLaunch", IF(AND(A6>='Campaign Metadata'!$B$3,A6<='Campaign Metadata'!$C$3),"ModelYCampaign", IF(AND(A6>='Campaign Metadata'!$B$4,A6<='Campaign Metadata'!$C$4),"FSDUpdate", IF(AND(A6>='Campaign Metadata'!$B$5,A6<='Campaign Metadata'!$C$5),"SustainabilityDrive","No Campaign")))) -> No Campaign | J6: =(C6-D6)/E6 -> 0.010517322
A7: 2024-06-10 | B7: Facebook | C7: 1697 | D7: 414 | E7: 316555 | F7: 2.37 | G7: 7924 | H7: =C7-D7 -> 1283 | I7: =IF(AND(A7>='Campaign Metadata'!$B$2,A7<='Campaign Metadata'!$C$2),"CybertruckLaunch", IF(AND(A7>='Campaign Metadata'!$B$3,A7<='Campaign Metadata'!$C$3),"ModelYCampaign", IF(AND(A7>='Campaign Metadata'!$B$4,A7<='Campaign Metadata'!$C$4),"FSDUpdate", IF(AND(A7>='Campaign Metadata'!$B$5,A7<='Campaign Metadata'!$C$5),"SustainabilityDrive","No Campaign")))) -> No Campaign | J7: =(C7-D7)/E7 -> 0.0040530082
A8: 2024-06-10 | B8: Twitter | C8: 436 | D8: 250 | E8: 254347 | F8: 4.01 | G8: 8912 | H8: =C8-D8 -> 186 | I8: =IF(AND(A8>='Campaign Metadata'!$B$2,A8<='Campaign Metadata'!$C$2),"CybertruckLaunch", IF(AND(A8>='Campaign Metadata'!$B$3,A8<='Campaign Metadata'!$C$3),"ModelYCampaign", IF(AND(A8>='Campaign Metadata'!$B$4,A8<='Campaign Metadata'!$C$4),"FSDUpdate", IF(AND(A8>='Campaign Metadata'!$B$5,A8<='Campaign Metadata'!$C$5),"SustainabilityDrive","No Campaign")))) -> No Campaign | J8: =(C8-D8)/E8 -> 0.00073128443
A9: 2024-06-10 | B9: YouTube | C9: 1197 | D9: 203 | E9: 413878 | F9: 3.16 | G9: 21205 | H9: =C9-D9 -> 994 | I9: =IF(AND(A9>='Campaign Metadata'!$B$2,A9<='Campaign Metadata'!$C$2),"CybertruckLaunch", IF(AND(A9>='Campaign Metadata'!$B$3,A9<='Campaign Metadata'!$C$3),"ModelYCampaign", IF(AND(A9>='Campaign Metadata'!$B$4,A9<='Campaign Metadata'!$C$4),"FSDUpdate", IF(AND(A9>='Campaign Metadata'!$B$5,A9<='Campaign Metadata'!$C$5),"SustainabilityDrive","No Campaign")))) -> No Campaign | J9: =(C9-D9)/E9 -> 0.0024016739
A10: 2024-06-17 | B10: Instagram | C10: 1048 | D10: 155 | E10: 456946 | F10: 2.46 | G10: 11329 | H10: =C10-D10 -> 893 | I10: =IF(AND(A10>='Campaign Metadata'!$B$2,A10<='Campaign Metadata'!$C$2),"CybertruckLaunch", IF(AND(A10>='Campaign Metadata'!$B$3,A10<='Campaign Metadata'!$C$3),"ModelYCampaign", IF(AND(A10>='Campaign Metadata'!$B$4,A10<='Campaign Metadata'!$C$4),"FSDUpdate", IF(AND(A10>='Campaign Metadata'!$B$5,A10<='Campaign Metadata'!$C$5),"SustainabilityDrive","No Campaign")))) -> CybertruckLaunch | J10: =(C10-D10)/E10 -> 0.0019542791
A11: 2024-06-17 | B11: Facebook | C11: 1753 | D11: 371 | E11: 169496 | F11: 8.11 | G11: 46670 | H11: =C11-D11 -> 1382 | I11: =IF(AND(A11>='Campaign Metadata'!$B$2,A11<='Campaign Metadata'!$C$2),"CybertruckLaunch", IF(AND(A11>='Campaign Metadata'!$B$3,A11<='Campaign Metadata'!$C$3),"ModelYCampaign", IF(AND(A11>='Campaign Metadata'!$B$4,A11<='Campaign Metadata'!$C$4),"FSDUpdate", IF(AND(A11>='Campaign Metadata'!$B$5,A11<='Campaign Metadata'!$C$5),"SustainabilityDrive","No Campaign")))) -> CybertruckLaunch | J11: =(C11-D11)/E11 -> 0.0081535847
A12: 2024-06-17 | B12: Twitter | C12: 1335 | D12: 40 | E12: 122732 | F12: 8.19 | G12: 22482 | H12: =C12-D12 -> 1295 | I12: =IF(AND(A12>='Campaign Metadata'!$B$2,A12<='Campaign Metadata'!$C$2),"CybertruckLaunch", IF(AND(A12>='Campaign Metadata'!$B$3,A12<='Campaign Metadata'!$C$3),"ModelYCampaign", IF(AND(A12>='Campaign Metadata'!$B$4,A12<='Campaign Metadata'!$C$4),"FSDUpdate", IF(AND(A12>='Campaign Metadata'!$B$5,A12<='Campaign Metadata'!$C$5),"SustainabilityDrive","No Campaign")))) -> CybertruckLaunch | J12: =(C12-D12)/E12 -> 0.010551445
A13: 2024-06-17 | B13: YouTube | C13: 403 | D13: 66 | E13: 382851 | F13: 3.49 | G13: 24313 | H13: =C13-D13 -> 337 | I13: =IF(AND(A13>='Campaign Metadata'!$B$2,A13<='Campaign Metadata'!$C$2),"CybertruckLaunch", IF(AND(A13>='Campaign Metadata'!$B$3,A13<='Campaign Metadata'!$C$3),"ModelYCampaign", IF(AND(A13>='Campaign Metadata'!$B$4,A13<='Campaign Metadata'!$C$4),"FSDUpdate", IF(AND(A13>='Campaign Metadata'!$B$5,A13<='Campaign Metadata'!$C$5),"SustainabilityDrive","No Campaign")))) -> CybertruckLaunch | J13: =(C13-D13)/E13 -> 0.000880238
... A201: 2025-05-12 | B201: YouTube | C201: 119 | D201: 456 | E201: 82558 | F201: 6.81 | G201: 12174 | H201: =C201-D201 -> -337 | I201: =IF(AND(A201>='Campaign Metadata'!$B$2,A201<='Campaign Metadata'!$C$2),"CybertruckLaunch", IF(AND(A201>='Campaign Metadata'!$B$3,A201<='Campaign Metadata'!$C$3),"ModelYCampaign", IF(AND(A201>='Campaign Metadata'!$B$4,A201<='Campaign Metadata'!$C$4),"FSDUpdate", IF(AND(A201>='Campaign Metadata'!$B$5,A201<='Campaign Metadata'!$C$5),"SustainabilityDrive","No Campaign")))) -> No Campaign | J201: =(C201-D201)/E201 -> -0.0040819787

Sheet Campaign Metadata
A1: Campaign_Name | B1: Start_Date | C1: End_Date | D1: Objective | E1: Total_Budget | F1: Target_Platforms | G1: Primary_Hashtags
A2: CybertruckLaunch | B2: 2024-06-15 | C2: 2024-07-15 | D2: Product Awareness | E2: 150000 | F2: Instagram,Facebook | G2: #EVRevolution,#TeslaCoInnovation
A3: ModelYCampaign | B3: 2024-10-01 | C3: 2024-10-31 | D3: Customer Engagement | E3: 200000 | F3: Instagram,YouTube | G3: #AnytimeIsTeslaTime,
A4: FSDUpdate | B4: 2024-12-25 | C4: 2025-01-10 | D4: Vehicle Launch | E4: 250000 | F4: Facebook,Twitter | G4: #SmoothLikeNitroTesla
A5: SustainabilityDrive | B5: 2025-03-01 | C5: 2025-03-31 | D5: Community Growth | E5: 180000 | F5: Instagram,Twitter | G5: #BetterWithTesla,#FutureOfDriving
